<?xml version="1.0" encoding="utf-8"?>
<!-- This URDF was automatically created by SolidWorks to URDF Exporter! Originally created by Stephen Brawner (brawner@gmail.com) 
     Commit Version: 1.6.0-4-g7f85cfe  Build Version: 1.6.7995.38578
     For more information, please see http://wiki.ros.org/sw_urdf_exporter -->
<robot
  name="urdf_robot_flo">
  <link
    name="base_link_flo">
    <inertial>
      <origin
        xyz="-6.2303E-07 1.2798E-06 0.072226"
        rpy="0 0 0" />
      <mass
        value="1.859" />
      <inertia
        ixx="0.011059"
        ixy="-1.2298E-07"
        ixz="-1.0999E-07"
        iyy="0.011058"
        iyz="1.8675E-07"
        izz="0.01313" />
    </inertial>
    <visual>
      <origin
        xyz="0 0 0"
        rpy="0 0 0" />
      <geometry>
        <mesh
          filename="package://urdf_robot_flo/meshes/base_link_flo.STL" />
      </geometry>
      <material
        name="">
        <color
          rgba="0.79216 0.81961 0.93333 1" />
      </material>
    </visual>
    <collision>
      <origin
        xyz="0 0 0"
        rpy="0 0 0" />
      <geometry>
        <mesh
          filename="package://urdf_robot_flo/meshes/base_link_flo.STL" />
      </geometry>
    </collision>
  </link>
  <link
    name="link_1_flo">
    <inertial>
      <origin
        xyz="1.4271E-08 -0.057735 -0.017263"
        rpy="0 0 0" />
      <mass
        value="0.32309" />
      <inertia
        ixx="0.00049732"
        ixy="6.7918E-11"
        ixz="-9.2494E-11"
        iyy="0.00037976"
        iyz="-4.0695E-05"
        izz="0.0004415" />
    </inertial>
    <visual>
      <origin
        xyz="0 0 0"
        rpy="0 0 0" />
      <geometry>
        <mesh
          filename="package://urdf_robot_flo/meshes/link_1_flo.STL" />
      </geometry>
      <material
        name="">
        <color
          rgba="0.79216 0.81961 0.93333 1" />
      </material>
    </visual>
    <collision>
      <origin
        xyz="0 0 0"
        rpy="0 0 0" />
      <geometry>
        <mesh
          filename="package://urdf_robot_flo/meshes/link_1_flo.STL" />
      </geometry>
    </collision>
  </link>
  <joint
    name="joint_1_flo"
    type="revolute">
    <origin
      xyz="0 0 0.15"
      rpy="-1.9468 0 3.1416" />
    <parent
      link="base_link_flo" />
    <child
      link="link_1_flo" />
    <axis
      xyz="0 0.93012 0.36725" />
    <limit
      lower="-3.1416"
      upper="3.1416"
      effort="0"
      velocity="0" />
  </joint>
  <link
    name="link_2_flo">
    <inertial>
      <origin
        xyz="1.0793E-08 0.052069 -0.14998"
        rpy="0 0 0" />
      <mass
        value="1.576" />
      <inertia
        ixx="0.017927"
        ixy="1.3734E-09"
        ixz="1.19E-09"
        iyy="0.017703"
        iyz="1.5043E-06"
        izz="0.0014816" />
    </inertial>
    <visual>
      <origin
        xyz="0 0 0"
        rpy="0 0 0" />
      <geometry>
        <mesh
          filename="package://urdf_robot_flo/meshes/link_2_flo.STL" />
      </geometry>
      <material
        name="">
        <color
          rgba="0.79216 0.81961 0.93333 1" />
      </material>
    </visual>
    <collision>
      <origin
        xyz="0 0 0"
        rpy="0 0 0" />
      <geometry>
        <mesh
          filename="package://urdf_robot_flo/meshes/link_2_flo.STL" />
      </geometry>
    </collision>
  </link>
  <joint
    name="joint_2_flo"
    type="revolute">
    <origin
      xyz="0 -0.07103 0.030818"
      rpy="1.1947 0 3.1416" />
    <parent
      link="link_1_flo" />
    <child
      link="link_2_flo" />
    <axis
      xyz="0 1 0" />
    <limit
      lower="-3.1416"
      upper="3.1416"
      effort="0"
      velocity="0" />
  </joint>
  <link
    name="link_3_flo">
    <inertial>
      <origin
        xyz="5.2044E-09 -0.058895 0.014691"
        rpy="0 0 0" />
      <mass
        value="0.41135" />
      <inertia
        ixx="0.00069097"
        ixy="6.2254E-11"
        ixz="2.363E-13"
        iyy="0.00055184"
        iyz="-2.4759E-05"
        izz="0.00052635" />
    </inertial>
    <visual>
      <origin
        xyz="0 0 0"
        rpy="0 0 0" />
      <geometry>
        <mesh
          filename="package://urdf_robot_flo/meshes/link_3_flo.STL" />
      </geometry>
      <material
        name="">
        <color
          rgba="0.79216 0.81961 0.93333 1" />
      </material>
    </visual>
    <collision>
      <origin
        xyz="0 0 0"
        rpy="0 0 0" />
      <geometry>
        <mesh
          filename="package://urdf_robot_flo/meshes/link_3_flo.STL" />
      </geometry>
    </collision>
  </link>
  <joint
    name="joint_3_flo"
    type="revolute">
    <origin
      xyz="0 0 -0.3"
      rpy="0 1.5708 0" />
    <parent
      link="link_2_flo" />
    <child
      link="link_3_flo" />
    <axis
      xyz="0 1 0" />
    <limit
      lower="-3.1416"
      upper="3.1416"
      effort="0"
      velocity="0" />
  </joint>
  <link
    name="link_4_flo">
    <inertial>
      <origin
        xyz="1.1592E-06 -0.057903 0.029233"
        rpy="0 0 0" />
      <mass
        value="0.54355" />
      <inertia
        ixx="0.0011348"
        ixy="6.5647E-11"
        ixz="5.5232E-11"
        iyy="0.00099434"
        iyz="-4.9821E-05"
        izz="0.00062037" />
    </inertial>
    <visual>
      <origin
        xyz="0 0 0"
        rpy="0 0 0" />
      <geometry>
        <mesh
          filename="package://urdf_robot_flo/meshes/link_4_flo.STL" />
      </geometry>
      <material
        name="">
        <color
          rgba="0.79216 0.81961 0.93333 1" />
      </material>
    </visual>
    <collision>
      <origin
        xyz="0 0 0"
        rpy="0 0 0" />
      <geometry>
        <mesh
          filename="package://urdf_robot_flo/meshes/link_4_flo.STL" />
      </geometry>
    </collision>
  </link>
  <joint
    name="joint_4_flo"
    type="revolute">
    <origin
      xyz="0 -0.05475 0.075"
      rpy="-1.5708 0 1.5708" />
    <parent
      link="link_3_flo" />
    <child
      link="link_4_flo" />
    <axis
      xyz="0 1 0" />
    <limit
      lower="-3.1416"
      upper="3.1416"
      effort="0"
      velocity="0" />
  </joint>
  <link
    name="link_5_flo">
    <inertial>
      <origin
        xyz="-1.2442E-06 -0.054708 0.01555"
        rpy="0 0 0" />
      <mass
        value="0.38783" />
      <inertia
        ixx="0.00063618"
        ixy="6.286E-11"
        ixz="2.3496E-11"
        iyy="0.00052928"
        iyz="-3.1119E-05"
        izz="0.00047736" />
    </inertial>
    <visual>
      <origin
        xyz="0 0 0"
        rpy="0 0 0" />
      <geometry>
        <mesh
          filename="package://urdf_robot_flo/meshes/link_5_flo.STL" />
      </geometry>
      <material
        name="">
        <color
          rgba="0.79216 0.81961 0.93333 1" />
      </material>
    </visual>
    <collision>
      <origin
        xyz="0 0 0"
        rpy="0 0 0" />
      <geometry>
        <mesh
          filename="package://urdf_robot_flo/meshes/link_5_flo.STL" />
      </geometry>
    </collision>
  </link>
  <joint
    name="joint_5_flo"
    type="revolute">
    <origin
      xyz="0 -0.054749 0.105"
      rpy="-1.5708 0 -3.1416" />
    <parent
      link="link_4_flo" />
    <child
      link="link_5_flo" />
    <axis
      xyz="0 1 0" />
    <limit
      lower="-3.1416"
      upper="3.1416"
      effort="0"
      velocity="0" />
  </joint>
  <link
    name="link_6_flo">
    <inertial>
      <origin
        xyz="1.5167E-05 4.219E-05 0.028173"
        rpy="0 0 0" />
      <mass
        value="0.2641" />
      <inertia
        ixx="0.00038852"
        ixy="-3.0807E-07"
        ixz="5.6453E-08"
        iyy="0.00039016"
        iyz="-1.4393E-07"
        izz="0.00071229" />
    </inertial>
    <visual>
      <origin
        xyz="0 0 0"
        rpy="0 0 0" />
      <geometry>
        <mesh
          filename="package://urdf_robot_flo/meshes/link_6_flo.STL" />
      </geometry>
      <material
        name="">
        <color
          rgba="0.79216 0.81961 0.93333 1" />
      </material>
    </visual>
    <collision>
      <origin
        xyz="0 0 0"
        rpy="0 0 0" />
      <geometry>
        <mesh
          filename="package://urdf_robot_flo/meshes/link_6_flo.STL" />
      </geometry>
    </collision>
  </link>
  <joint
    name="joint_6_flo"
    type="revolute">
    <origin
      xyz="0 -0.049499 0.075"
      rpy="0 0 0" />
    <parent
      link="link_5_flo" />
    <child
      link="link_6_flo" />
    <axis
      xyz="0 0 1" />
    <limit
      lower="-3.1416"
      upper="3.1416"
      effort="0"
      velocity="0" />
  </joint>
</robot>